Workbook

Sheet STDs and Samples
A2: Project: TEMPEST | F2: Notes: We had power issues during this run. This is why there is "MISSING" data in the STD's chart
A3: Measurement: Soil Air [CH4] and [CO2]
A4: Analyst: AES
A6: Collection Date | B6: Run Date | C6: Plot | D6: Grid Square | E6: Depth | F6: Sample ID | G6: CH4 Peak Area | H6: CO2 Peak Area | I6: CH4 (ppm) | J6: CO2 (ppm) | L6: CH4 Standard Curve
A7: 44417 | B7: 44418 | C7: Control | D7: C3 | E7: 10 | F7: 1 | G7: 1031 | H7: 496749 | I7: =(G7*$AA$14)+$AA$15 -> 1.0593409 | J7: =(H7*$AA$29)+$AA$30 -> 3626.1119 | L7: Tank | M7: ppm | N7: Peak Area | O7: Ave ppm | P7: Ave Peak Area
A8: 44417 | B8: 44418 | C8: Control | D8: C3 | E8: 20 | F8: 2 | G8: 550 | H8: 1011836 | I8: =(G8*$AA$14)+$AA$15 -> 0.036136018 | J8: =(H8*$AA$29)+$AA$30 -> 7410.7473 | L8: TRI-STD1 | M8: 7.5 | N8: 3505 | O8: =AVERAGE(M8:M10) -> 7.5 | P8: =AVERAGE(N8:N9) -> 3958
A9: 44417 | B9: 44418 | C9: Control | D9: C3 | E9: 35 | F9: 3 | G9: 839 | H9: 1253516 | I9: =(G9*$AA$14)+$AA$15 -> 0.65090983 | J9: =(H9*$AA$29)+$AA$30 -> 9186.5068 | L9: TRI-STD1 | M9: 7.5 | N9: 4411
A10: 44417 | B10: 44418 | C10: Control | D10: C3 | E10: 50 | F10: 4 | G10: 350 | H10: 2115149 | I10: =(G10*$AA$14)+$AA$15 -> -0.38931299 | J10: =(H10*$AA$29)+$AA$30 -> 15517.411 | L10: TRI-STD1 | M10: 7.5 | N10: MISSING
A11: 44417 | B11: 44418 | C11: Control | D11: C6 | E11: 10 | F11: 5 | G11: 1383 | H11: 692649 | I11: =(G11*$AA$14)+$AA$15 -> 1.8081311 | J11: =(H11*$AA$29)+$AA$30 -> 5065.5 | L11: TRI-STD2 | M11: 5 | N11: 2786 | O11: =AVERAGE(M11:M13) -> 5 | P11: =AVERAGE(N11:N13) -> 2939.6667
A12: 44417 | B12: 44418 | C12: Control | D12: C6 | E12: 20 | F12: 6 | G12: 945 | H12: 1205718 | I12: =(G12*$AA$14)+$AA$15 -> 0.8763978 | J12: =(H12*$AA$29)+$AA$30 -> 8835.3079 | L12: TRI-STD2 | M12: 5 | N12: 3097
A13: 44417 | B13: 44418 | C13: Control | D13: C6 | E13: 35 | F13: 7 | G13: 760 | H13: 2444514 | I13: =(G13*$AA$14)+$AA$15 -> 0.48285747 | J13: =(H13*$AA$29)+$AA$30 -> 17937.442 | L13: TRI-STD2 | M13: 5 | N13: 2936
A14: 44417 | B14: 44418 | C14: Control | D14: C6 | E14: 50 | F14: 8 | G14: 694 | H14: 2394473 | I14: =(G14*$AA$14)+$AA$15 -> 0.3424593 | J14: =(H14*$AA$29)+$AA$30 -> 17569.763 | L14: TRI-STD3 | M14: 3 | N14: 2068 | O14: =AVERAGE(M14:M16) -> 3 | P14: =AVERAGE(N14:N16) -> 2057.6667 | Z14: slope | AA14: =SLOPE(O8:O22,P8:P22) -> 0.002127245
A15: 44417 | B15: 44418 | C15: Control | D15: F4 | E15: 10 | F15: 9 | G15: 995 | H15: 443878 | I15: =(G15*$AA$14)+$AA$15 -> 0.98276005 | J15: =(H15*$AA$29)+$AA$30 -> 3237.6388 | L15: TRI-STD3 | M15: 3 | N15: 2062 | Z15: intercept | AA15: =INTERCEPT(O8:O22,P8:P22) -> -1.1338487
A16: 44417 | B16: 44418 | C16: Control | D16: F4 | E16: 20 | F16: 10 | G16: 1869 | H16: 1068231 | I16: =(G16*$AA$14)+$AA$15 -> 2.8419722 | J16: =(H16*$AA$29)+$AA$30 -> 7825.1132 | L16: TRI-STD3 | M16: 3 | N16: 2043 | Z16: r2 | AA16: =RSQ(O8:O22,P8:P22) -> 0.99307451
A17: 44417 | B17: 44418 | C17: Control | D17: F4 | E17: 35 | F17: 11 | G17: 1426 | H17: 983377 | I17: =(G17*$AA$14)+$AA$15 -> 1.8996027 | J17: =(H17*$AA$29)+$AA$30 -> 7201.6429 | L17: TRI-STD4 | M17: 1.5 | N17: 1354 | O17: =AVERAGE(M17:M19) -> 1.5 | P17: =AVERAGE(N17:N19) -> 1301.6667
A18: 44417 | B18: 44418 | C18: Control | D18: F4 | E18: 50 | F18: 12 | G18: 479 | H18: 1667386 | I18: =(G18*$AA$14)+$AA$15 -> -0.11489838 | J18: =(H18*$AA$29)+$AA$30 -> 12227.444 | L18: TRI-STD4 | M18: 1.5 | N18: 1292
A19: 44417 | B19: 44418 | C19: Control | D19: H3 | E19: 10 | F19: 13 | G19: 647 | H19: 540934 | I19: =(G19*$AA$14)+$AA$15 -> 0.24247879 | J19: =(H19*$AA$29)+$AA$30 -> 3950.7641 | L19: TRI-STD4 | M19: 1.5 | N19: 1259
A20: 44417 | B20: 44418 | C20: Control | D20: H3 | E20: 20 | F20: 14 | G20: 427 | H20: 1074096 | I20: =(G20*$AA$14)+$AA$15 -> -0.22551512 | J20: =(H20*$AA$29)+$AA$30 -> 7868.2067 | L20: TRI-STD5 | M20: 0.5 | N20: 747 | O20: =AVERAGE(M20:M22) -> 0.5 | P20: =AVERAGE(N20:N22) -> 634.66667
A21: 44417 | B21: 44418 | C21: Control | D21: H3 | E21: 35 | F21: 15 | G21: 472 | H21: 1155764 | I21: =(G21*$AA$14)+$AA$15 -> -0.12978909 | J21: =(H21*$AA$29)+$AA$30 -> 8468.2676 | L21: TRI-STD5 | M21: 0.5 | N21: 659
A22: 44417 | B22: 44418 | C22: Control | D22: H3 | E22: 50 | F22: 16 | G22: 412 | H22: 1480423 | I22: =(G22*$AA$14)+$AA$15 -> -0.2574238 | J22: =(H22*$AA$29)+$AA$30 -> 10853.721 | L22: TRI-STD5 | M22: 0.5 | N22: 498
A23: 44417 | B23: 44418 | C23: Control | D23: H6 | E23: 10 | F23: 17 | G23: 876 | H23: 336402 | I23: =(G23*$AA$14)+$AA$15 -> 0.7296179 | J23: =(H23*$AA$29)+$AA$30 -> 2447.9519
A24: 44417 | B24: 44418 | C24: Control | D24: H6 | E24: 20 | F24: 18 | G24: 386 | H24: 966625 | I24: =(G24*$AA$14)+$AA$15 -> -0.31273217 | J24: =(H24*$AA$29)+$AA$30 -> 7078.5565 | L24: CO2 Standard Curve
A25: 44417 | B25: 44418 | C25: Control | D25: H6 | E25: 35 | F25: 19 | G25: 278 | H25: 1838289 | I25: =(G25*$AA$14)+$AA$15 -> -0.54247463 | J25: =(H25*$AA$29)+$AA$30 -> 13483.165 | L25: Tank | M25: ppm | N25: Peak Area | O25: Ave ppm | P25: Ave Peak Area
A26: 44417 | B26: 44418 | C26: Control | D26: H6 | E26: 50 | F26: 20 | G26: 294 | H26: 2088679 | I26: =(G26*$AA$14)+$AA$15 -> -0.50843871 | J26: =(H26*$AA$29)+$AA$30 -> 15322.921 | L26: TRI-STD1 | M26: 1375 | N26: 174399 | O26: =AVERAGE(M26:M28) -> 1375 | P26: =AVERAGE(N26:N27) -> 191272
A27: 44417 | B27: 44418 | C27: Freshwater | D27: C3 | E27: 10 | F27: 21 | G27: 908 | H27: 382337 | I27: =(G27*$AA$14)+$AA$15 -> 0.79768974 | J27: =(H27*$AA$29)+$AA$30 -> 2785.4623 | L27: TRI-STD1 | M27: 1375 | N27: 208145
A28: 44417 | B28: 44418 | C28: Freshwater | D28: C3 | E28: 20 | F28: 22 | G28: 618 | H28: 763667 | I28: =(G28*$AA$14)+$AA$15 -> 0.18078868 | J28: =(H28*$AA$29)+$AA$30 -> 5587.3093 | L28: TRI-STD1 | M28: 1375 | N28: MISSING
A29: 44417 | B29: 44418 | C29: Freshwater | D29: C3 | E29: 35 | F29: 23 | G29: 639 | H29: 1031712 | I29: =(G29*$AA$14)+$AA$15 -> 0.22546083 | J29: =(H29*$AA$29)+$AA$30 -> 7556.7875 | L29: TRI-STD2 | M29: 916.7 | N29: 131886 | O29: =AVERAGE(M29:M31) -> 916.7 | P29: =AVERAGE(N29:N31) -> 137132 | Z29: slope | AA29: =SLOPE(O26:O43,P26:P43) -> 0.0073475652
A30: 44417 | B30: 44418 | C30: Freshwater | D30: C3 | E30: 50 | F30: 24 | G30: 557 | H30: 1650633 | I30: =(G30*$AA$14)+$AA$15 -> 0.051026733 | J30: =(H30*$AA$29)+$AA$30 -> 12104.35 | L30: TRI-STD2 | M30: 916.7 | N30: 144155 | Z30: intercept | AA30: =INTERCEPT(O26:O43,P26:P43) -> -23.783743
A31: 44417 | B31: 44418 | C31: Freshwater | D31: C6 | E31: 10 | F31: 25 | G31: 1023 | H31: 286251 | I31: =(G31*$AA$14)+$AA$15 -> 1.0423229 | J31: =(H31*$AA$29)+$AA$30 -> 2079.4641 | L31: TRI-STD2 | M31: 916.7 | N31: 135355 | Z31: r2 | AA31: =RSQ(O26:O43,P26:P43) -> 0.99660016
A32: 44417 | B32: 44418 | C32: Freshwater | D32: C6 | E32: 20 | F32: 26 | G32: 701 | H32: 601744 | I32: =(G32*$AA$14)+$AA$15 -> 0.35735002 | J32: =(H32*$AA$29)+$AA$30 -> 4397.5695 | L32: TRI-STD3 | M32: 550 | N32: 92020 | O32: =AVERAGE(M32:M34) -> 550 | P32: =AVERAGE(N32:N34) -> 92310
A33: 44417 | B33: 44418 | C33: Freshwater | D33: C6 | E33: 35 | F33: 27 | G33: 895 | H33: 909029 | I33: =(G33*$AA$14)+$AA$15 -> 0.77003555 | J33: =(H33*$AA$29)+$AA$30 -> 6655.3661 | L33: TRI-STD3 | M33: 550 | N33: 92542
A34: 44417 | B34: 44418 | C34: Freshwater | D34: C6 | E34: 50 | F34: 28 | G34: 496 | H34: 1276474 | I34: =(G34*$AA$14)+$AA$15 -> -0.078735213 | J34: =(H34*$AA$29)+$AA$30 -> 9355.1922 | L34: TRI-STD3 | M34: 550 | N34: 92368
A35: 44417 | B35: 44418 | C35: Freshwater | D35: F4 | E35: 10 | F35: 29 | G35: 1013 | H35: 300150 | I35: =(G35*$AA$14)+$AA$15 -> 1.0210505 | J35: =(H35*$AA$29)+$AA$30 -> 2181.588 | L35: TRI-STD4 | M35: 275 | N35: 74634 | O35: =AVERAGE(M35:M37) -> 275 | P35: =AVERAGE(N35:N37) -> 61622.333
A36: 44417 | B36: 44418 | C36: Freshwater | D36: F4 | E36: 20 | F36: 30 | G36: 693 | H36: 556910 | I36: =(G36*$AA$14)+$AA$15 -> 0.34033206 | J36: =(H36*$AA$29)+$AA$30 -> 4068.1488 | L36: TRI-STD4 | M36: 275 | N36: 54293
A37: 44417 | B37: 44418 | C37: Freshwater | D37: F4 | E37: 35 | F37: 31 | G37: 580 | H37: 812594 | I37: =(G37*$AA$14)+$AA$15 -> 0.099953369 | J37: =(H37*$AA$29)+$AA$30 -> 5946.8037 | L37: TRI-STD4 | M37: 275 | N37: 55940
A38: 44417 | B38: 44418 | C38: Freshwater | D38: F4 | E38: 50 | F38: 32 | G38: 520 | H38: 1344881 | I38: =(G38*$AA$14)+$AA$15 -> -0.027681333 | J38: =(H38*$AA$29)+$AA$30 -> 9857.8171 | L38: TRI-STD5 | M38: 91.7 | N38: 26947 | O38: =AVERAGE(M38:M40) -> 91.7 | P38: =AVERAGE(N38:N40) -> 24209.333
A39: 44417 | B39: 44418 | C39: Freshwater | D39: H3 | E39: 10 | F39: 33 | G39: 971 | H39: 253917 | I39: =(G39*$AA$14)+$AA$15 -> 0.93170617 | J39: =(H39*$AA$29)+$AA$30 -> 1841.888 | L39: TRI-STD5 | M39: 91.7 | N39: 25735
A40: 44417 | B40: 44418 | C40: Freshwater | D40: H3 | E40: 20 | F40: 34 | G40: 685 | H40: 493212 | I40: =(G40*$AA$14)+$AA$15 -> 0.3233141 | J40: =(H40*$AA$29)+$AA$30 -> 3600.1236 | L40: TRI-STD5 | M40: 91.7 | N40: 19946
A41: 44417 | B41: 44418 | C41: Freshwater | D41: H3 | E41: 35 | F41: 35 | G41: 614 | H41: 613679 | I41: =(G41*$AA$14)+$AA$15 -> 0.1722797 | J41: =(H41*$AA$29)+$AA$30 -> 4485.2627 | L41: 2500 ppm | M41: 2500 | N41: 314935 | O41: =AVERAGE(M41:M41) -> 2500 | P41: =AVERAGE(N41) -> 314935
A42: 44417 | B42: 44418 | C42: Freshwater | D42: H3 | E42: 50 | F42: 36 | G42: 597 | H42: 854431 | I42: =(G42*$AA$14)+$AA$15 -> 0.13611653 | J42: =(H42*$AA$29)+$AA$30 -> 6254.2038 | L42: 5000 ppm | M42: 5000 | N42: 631430 | O42: =AVERAGE(M42:M42) -> 5000 | P42: =AVERAGE(N42) -> 631430
...

Sheet Sheet1
A1: Plot | B1: Grid Square | C1: Depth | D1: CH4 (ppm) | E1: CO2 (ppm) | F1: Temp | G1: VWC | H1: EC | J1: Ave CH4 (ppm) | K1: CH4 SD | L1: CH4 SE | M1: Ave CO2 (ppm) | N1: CO2 SD | O1: CO2 SE
A2: Control | B2: C3 | C2: 10 | D2: =('STDs and Samples'!I7) -> 1.0593409 | E2: =('STDs and Samples'!J7) -> 3626.1119 | J2: =AVERAGE(D2:D6) -> 0.96446575 | K2: =STDEV(D2:D6) -> 0.56954498 | L2: =K2/SQRT(5) -> 0.25470826 | M2: =AVERAGE(E2:E6) -> 3665.5933 | N2: =STDEV(E2:E6) -> 962.86233 | O2: =N2/SQRT(5) -> 430.60512
A3: Control | B3: C6 | C3: 10 | D3: =('STDs and Samples'!I11) -> 1.8081311 | E3: =('STDs and Samples'!J11) -> 5065.5
A4: Control | B4: F4 | C4: 10 | D4: =('STDs and Samples'!I15) -> 0.98276005 | E4: =('STDs and Samples'!J15) -> 3237.6388
A5: Control | B5: H3 | C5: 10 | D5: =('STDs and Samples'!I19) -> 0.24247879 | E5: =('STDs and Samples'!J19) -> 3950.7641
A6: Control | B6: H6 | C6: 10 | D6: =('STDs and Samples'!I23) -> 0.7296179 | E6: =('STDs and Samples'!J23) -> 2447.9519
A7: Control | B7: C3 | C7: 20 | D7: =('STDs and Samples'!I8) -> 0.036136018 | E7: =('STDs and Samples'!J8) -> 7410.7473 | J7: =AVERAGE(D7:D11) -> 0.64325175 | K7: =STDEV(D7:D11) -> 1.3158628 | L7: =K7/SQRT(5) -> 0.58847172 | M7: =AVERAGE(E7:E11) -> 7803.5863 | N7: =STDEV(E7:E11) -> 661.26383 | O7: =N7/SQRT(5) -> 295.72617
A8: Control | B8: C6 | C8: 20 | D8: =('STDs and Samples'!I12) -> 0.8763978 | E8: =('STDs and Samples'!J12) -> 8835.3079
A9: Control | B9: F4 | C9: 20 | D9: =('STDs and Samples'!I16) -> 2.8419722 | E9: =('STDs and Samples'!J16) -> 7825.1132
A10: Control | B10: H3 | C10: 20 | D10: =('STDs and Samples'!I20) -> -0.22551512 | E10: =('STDs and Samples'!J20) -> 7868.2067
A11: Control | B11: H6 | C11: 20 | D11: =('STDs and Samples'!I24) -> -0.31273217 | E11: =('STDs and Samples'!J24) -> 7078.5565
A12: Control | B12: C3 | C12: 35 | D12: =('STDs and Samples'!I9) -> 0.65090983 | E12: =('STDs and Samples'!J9) -> 9186.5068 | J12: =AVERAGE(D12:D16) -> 0.47222125 | K12: =STDEV(D12:D16) -> 0.93025327 | L12: =K12/SQRT(5) -> 0.41602191 | M12: =AVERAGE(E12:E16) -> 11255.405 | N12: =STDEV(E12:E16) -> 4418.5404 | O12: =N12/SQRT(5) -> 1976.0313
A13: Control | B13: C6 | C13: 35 | D13: =('STDs and Samples'!I13) -> 0.48285747 | E13: =('STDs and Samples'!J13) -> 17937.442
A14: Control | B14: F4 | C14: 35 | D14: =('STDs and Samples'!I17) -> 1.8996027 | E14: =('STDs and Samples'!J17) -> 7201.6429
A15: Control | B15: H3 | C15: 35 | D15: =('STDs and Samples'!I21) -> -0.12978909 | E15: =('STDs and Samples'!J21) -> 8468.2676
A16: Control | B16: H6 | C16: 35 | D16: =('STDs and Samples'!I25) -> -0.54247463 | E16: =('STDs and Samples'!J25) -> 13483.165
A17: Control | B17: C3 | C17: 50 | D17: =('STDs and Samples'!I10) -> -0.38931299 | E17: =('STDs and Samples'!J10) -> 15517.411 | J17: =AVERAGE(D17:D21) -> -0.18552291 | K17: =STDEV(D17:D21) -> 0.32966945 | L17: =K17/SQRT(5) -> 0.14743266 | M17: =AVERAGE(E17:E21) -> 14298.252 | N17: =STDEV(E17:E21) -> 2710.7251 | O17: =N17/SQRT(5) -> 1212.2731
A18: Control | B18: C6 | C18: 50 | D18: =('STDs and Samples'!I14) -> 0.3424593 | E18: =('STDs and Samples'!J14) -> 17569.763
A19: Control | B19: F4 | C19: 50 | D19: =('STDs and Samples'!I18) -> -0.11489838 | E19: =('STDs and Samples'!J18) -> 12227.444
A20: Control | B20: H3 | C20: 50 | D20: =('STDs and Samples'!I22) -> -0.2574238 | E20: =('STDs and Samples'!J22) -> 10853.721
A21: Control | B21: H6 | C21: 50 | D21: =('STDs and Samples'!I26) -> -0.50843871 | E21: =('STDs and Samples'!J26) -> 15322.921
A22: Freshwater | B22: C3 | C22: 10 | D22: =('STDs and Samples'!I27) -> 0.79768974 | E22: =('STDs and Samples'!J27) -> 2785.4623 | J22: =AVERAGE(D22:D26) -> 1.0036071 | K22: =STDEV(D22:D26) -> 0.15692956 | L22: =K22/SQRT(5) -> 0.070181034 | M22: =AVERAGE(E22:E26) -> 2165.751 | N22: =STDEV(E22:E26) -> 369.94256 | O22: =N22/SQRT(5) -> 165.44334
A23: Freshwater | B23: C6 | C23: 10 | D23: =('STDs and Samples'!I31) -> 1.0423229 | E23: =('STDs and Samples'!J31) -> 2079.4641
A24: Freshwater | B24: F4 | C24: 10 | D24: =('STDs and Samples'!I35) -> 1.0210505 | E24: =('STDs and Samples'!J35) -> 2181.588
A25: Freshwater | B25: H3 | C25: 10 | D25: =('STDs and Samples'!I39) -> 0.93170617 | E25: =('STDs and Samples'!J39) -> 1841.888
A26: Freshwater | B26: H6 | C26: 10 | D26: =('STDs and Samples'!I43) -> 1.225266 | E26: =('STDs and Samples'!J43) -> 1940.3527
A27: Freshwater | B27: C3 | C27: 20 | D27: =('STDs and Samples'!I28) -> 0.18078868 | E27: =('STDs and Samples'!J28) -> 5587.3093 | J27: =AVERAGE(D27:D31) -> 0.29778716 | K27: =STDEV(D27:D31) -> 0.070376133 | L27: =K27/SQRT(5) -> 0.031473163 | M27: =AVERAGE(E27:E31) -> 4300.6361 | N27: =STDEV(E27:E31) -> 776.6497 | O27: =N27/SQRT(5) -> 347.3283
A28: Freshwater | B28: C6 | C28: 20 | D28: =('STDs and Samples'!I32) -> 0.35735002 | E28: =('STDs and Samples'!J32) -> 4397.5695
A29: Freshwater | B29: F4 | C29: 20 | D29: =('STDs and Samples'!I36) -> 0.34033206 | E29: =('STDs and Samples'!J36) -> 4068.1488
A30: Freshwater | B30: H3 | C30: 20 | D30: =('STDs and Samples'!I40) -> 0.3233141 | E30: =('STDs and Samples'!J40) -> 3600.1236
A31: Freshwater | B31: H6 | C31: 20 | D31: =('STDs and Samples'!I44) -> 0.28715093 | E31: =('STDs and Samples'!J44) -> 3850.029
A32: Freshwater | B32: C3 | C32: 35 | D32: =('STDs and Samples'!I29) -> 0.22546083 | E32: =('STDs and Samples'!J29) -> 7556.7875 | J32: =AVERAGE(D32:D36) -> 0.29565991 | K32: =STDEV(D32:D36) -> 0.26959421 | L32: =K32/SQRT(5) -> 0.1205662 | M32: =AVERAGE(E32:E36) -> 6002.1205 | N32: =STDEV(E32:E36) -> 1178.1128 | O32: =N32/SQRT(5) -> 526.86806
A33: Freshwater | B33: C6 | C33: 35 | D33: =('STDs and Samples'!I33) -> 0.77003555 | E33: =('STDs and Samples'!J33) -> 6655.3661
A34: Freshwater | B34: F4 | C34: 35 | D34: =('STDs and Samples'!I37) -> 0.099953369 | E34: =('STDs and Samples'!J37) -> 5946.8037
A35: Freshwater | B35: H3 | C35: 35 | D35: =('STDs and Samples'!I41) -> 0.1722797 | E35: =('STDs and Samples'!J41) -> 4485.2627
A36: Freshwater | B36: H6 | C36: 35 | D36: =('STDs and Samples'!I45) -> 0.21057011 | E36: =('STDs and Samples'!J45) -> 5366.3828
A37: Freshwater | B37: C3 | C37: 50 | D37: =('STDs and Samples'!I30) -> 0.051026733 | E37: =('STDs and Samples'!J30) -> 12104.35 | J37: =AVERAGE(D37:D41) -> 0.011034527 | K37: =STDEV(D37:D41) -> 0.0838766 | L37: =K37/SQRT(5) -> 0.037510756 | M37: =AVERAGE(E37:E41) -> 9167.0725 | N37: =STDEV(E37:E41) -> 2147.1389 | O37: =N37/SQRT(5) -> 960.22971
A38: Freshwater | B38: C6 | C38: 50 | D38: =('STDs and Samples'!I34) -> -0.078735213 | E38: =('STDs and Samples'!J34) -> 9355.1922
A39: Freshwater | B39: F4 | C39: 50 | D39: =('STDs and Samples'!I38) -> -0.027681333 | E39: =('STDs and Samples'!J38) -> 9857.8171
A40: Freshwater | B40: H3 | C40: 50 | D40: =('STDs and Samples'!I42) -> 0.13611653 | E40: =('STDs and Samples'!J42) -> 6254.2038
...
